data/tick_data_sample.csv
timestamp,type,side,price,qty
1000000,ADD,buy,100.00,500
1000050,ADD,sell,100.05,200
1000100,ADD,sell,100.10,300
1000200,ADD,buy,100.00,150
1000350,ADD,buy,99.95,1000
1005000,CANCEL,sell,100.10,300
1008000,ADD,buy,100.05,50
1010000,TRADE,buy,100.05,50
1010000,TRADE,buy,100.05,150
1012000,ADD,sell,100.05,25
1025000,ADD,sell,100.05,100
1030000,CANCEL,buy,99.95,500
1040000,TRADE,sell,100.00,100
1050000,ADD,buy,100.00,200
